Workbook

Sheet 112225
B1: Date | C1: Time | D1: Well Name | E1: Tank | F1: Oil (ft) | G1: Oil (in) | H1: Gas Rate | I1: Instant Gas Rate | J1: Tubing Pressure (psi) | K1: Casing Pressure (psi) | L1: Line Pressure (psi) | M1: Comments/Issues
A2: 1 | B2: 45983 | C2: 0.41666667 | D2: RALPH BAKER 1 | F2: 3 | G2: 10 | H2: 24 | I2: 27 | J2: 120 | L2: 38 | M2: Running
A3: 2 | B3: 45983 | D3: SALLY 1-12H | F3: 2 | G3: 6 | H3: 174 | I3: 180 | J3: 150 | K3: 30 | L3: 36 | M3: Running
A4: 3 | B4: 45983 | D4: ANITA 1-13H | F4: 1 | G4: 0 | H4: 33 | I4: 104 | J4: 200 | K4: 50 | L4: 44 | M4: Running, oil ticket picked up, rejected
A5: 4 | B5: 45983 | D5: ARIANA 1-18H | F5: 2 | G5: 2 | H5: 127 | I5: 107 | J5: 150 | K5: 20 | L5: 42 | M5: Running
A6: 5 | B6: 45983 | D6: CLAY 1-6H | F6: 2 | G6: 9 | H6: 230 | I6: 240 | J6: 160 | L6: 37 | M6: Running
A7: 6 | B7: 45983 | D7: ARIANA 1-7H | F7: 1 | G7: 10 | H7: 175 | I7: 180 | J7: 80 | K7: 50 | L7: 36 | M7: Running
A8: 7 | B8: 45983 | D8: PEPPER 3-4H | F8: 1 | G8: 11 | H8: 54 | I8: 176 | J8: 130 | K8: 50 | L8: 33 | M8: Running
A9: 8 | B9: 45983 | D9: PEPPER 4-4H | H9: 77 | I9: 91 | J9: 75 | K9: 30 | L9: 33 | M9: Running
A10: 9 | B10: 45983 | D10: BIRD 3319 1-6 | F10: 1 | G10: 7 | H10: 0 | I10: 0 | J10: 150 | K10: 50 | L10: 33 | M10: Running
A11: 10 | B11: 45983 | D11: BIRD 3319 3-6 | H11: 44 | I11: 39 | L11: 32 | M11: CDP 50
A12: 11 | B12: 45983 | D12: JELLISON A 11-5 | F12: 1 | G12: 8 | J12: 100 | K12: 50 | M12: Running
A13: 12 | B13: 45983 | D13: ROCK 3319 1-16H | F13: 2 | G13: 2 | H13: 100 | I13: 27 | J13: 120 | K13: 20 | L13: 30 | M13: Down, reset, running, texted Ron
A14: 13 | B14: 45983 | D14: Dixie 3120 1‐25 SWD | M14: 5610222, Running
A15: 14 | B15: 45983 | D15: GARLAND 1-26H | F15: 2 | G15: 7 | H15: 40 | I15: 0 | J15: 150 | K15: 43 | L15: 76 | M15: Running
A16: 15 | B16: 45983 | D16: PTL 1-15H | F16: 5 | G16: 5 | H16: 56 | I16: 47 | J16: 120 | L16: 50 | M16: Running
A17: 16 | B17: 45983 | D17: GABRIEL 2-12H | F17: 5 | G17: 8 | H17: 47 | I17: 20 | J17: 200 | K17: 50 | L17: 56 | M17: Running, oil ticket
A18: 17 | B18: 45983 | D18: GABRIEL 1-12H | F18: 3 | G18: 5 | H18: 42 | I18: 140 | J18: 120 | K18: 50 | L18: 56 | M18: Running, oil ticket
A19: 18 | B19: 45983 | D19: SEAN 1-18H | F19: 7 | G19: 1 | H19: 60 | I19: 65 | J19: 150 | K19: 50 | L19: 56 | M19: Running
A20: 19 | B20: 45983 | D20: SEAN 3119 3-18H | F20: 1 | G20: 11 | H20: 40 | I20: 129 | J20: 150 | K20: 50 | L20: 58 | M20: Running
A21: 20 | B21: 45983 | D21: ELLIS 2-19H | F21: 4 | G21: 0 | H21: 87 | I21: 99 | J21: 150 | K21: 50 | L21: 57 | M21: Running
A22: 21 | B22: 45983 | D22: BROTHERS 1-6H | F22: 4 | G22: 2 | H22: 10 | I22: 62 | J22: 100 | K22: 50 | L22: 65 | M22: Running
A23: 22 | B23: 45983 | D23: BROTHERS 2-6H | F23: 2 | G23: 11 | H23: 84 | I23: 15 | J23: 80 | K23: 50 | L23: 74 | M23: Running
A24: 23 | B24: 45983 | D24: SARAH 1-34H
A25: 24 | B25: 45983 | D25: SARAH 2-34H
A26: 25 | B26: 45983 | D26: WANDA 1-2H 1L
A27: 26 | B27: 45983 | D27: Yankee 3317 1-27 SWD
A28: 27
A29: 28
A30: 29
A31: 30
A32: 31
A33: 32
A34: 33
A35: 34
A36: 35
A37: 36
H38: =SUM(H1:H37) -> 1504

Sheet 112325
B1: Date | C1: Time | D1: Well Name | E1: Tank | F1: Oil (ft) | G1: Oil (in) | H1: Gas Rate | I1: Instant Gas Rate | J1: Tubing Pressure (psi) | K1: Casing Pressure (psi) | L1: Line Pressure (psi) | M1: Comments/Issues
A2: 1 | B2: 45984 | C2: 0.57291667 | D2: ='112225'!D2 -> RALPH BAKER 1 | F2: 3 | G2: 10 | H2: 24 | I2: 29 | J2: 120 | L2: 33 | M2: Running
A3: 2 | B3: 45984 | C3: 0.57986111 | D3: ='112225'!D3 -> SALLY 1-12H | F3: 2 | G3: 6 | H3: 169 | I3: 190 | J3: 150 | K3: 30 | L3: 36 | M3: Running
A4: 3 | B4: 45984 | C4: 0.58680556 | D4: ='112225'!D4 -> ANITA 1-13H | F4: 1 | G4: 0 | H4: 90 | I4: 93 | J4: 200 | K4: 50 | L4: 43 | M4: Running
A5: 4 | B5: 45984 | C5: 0.59375 | D5: ='112225'!D5 -> ARIANA 1-18H | F5: 2 | G5: 2 | H5: 124 | I5: 115 | J5: 150 | K5: 30 | L5: 43 | M5: Running
A6: 5 | B6: 45984 | C6: 0.60416667 | D6: ='112225'!D6 -> CLAY 1-6H | F6: 2 | G6: 9 | H6: 231 | I6: 229 | J6: 150 | K6: 20 | L6: 37 | M6: Running
A7: 6 | B7: 45984 | C7: 0.61111111 | D7: ='112225'!D7 -> ARIANA 1-7H | F7: 1 | G7: 10 | H7: 187 | I7: 206 | J7: 80 | K7: 50 | L7: 36 | M7: Running
A8: 7 | B8: 45984 | C8: 0.61944444 | D8: ='112225'!D8 -> PEPPER 3-4H | F8: 1 | G8: 11 | H8: 140 | I8: 40 | J8: 130 | K8: 50 | L8: 32 | M8: Running
A9: 8 | B9: 45984 | C9: 0.62291667 | D9: ='112225'!D9 -> PEPPER 4-4H | H9: 85 | I9: 97 | J9: 75 | K9: 30 | L9: 32 | M9: Running
A10: 9 | B10: 45984 | C10: 0.64583333 | D10: ='112225'!D10 -> BIRD 3319 1-6 | F10: 1 | G10: 7 | H10: 0 | I10: 0 | J10: 150 | K10: 50 | L10: 33 | M10: Running
A11: 10 | B11: 45984 | D11: ='112225'!D11 -> BIRD 3319 3-6 | H11: 39 | I11: 53 | L11: 34 | M11: Running
A12: 11 | B12: 45984 | D12: ='112225'!D12 -> JELLISON A 11-5 | F12: 1 | G12: 8 | J12: 10 | K12: 50 | M12: Running CDP 46
A13: 12 | B13: 45984 | C13: 0.63541667 | D13: ='112225'!D13 -> ROCK 3319 1-16H | F13: 2 | G13: 2
A14: 13 | B14: 45984 | D14: ='112225'!D14 -> Dixie 3120 1‐25 SWD
A15: 14 | B15: 45984 | D15: ='112225'!D15 -> GARLAND 1-26H
A16: 15 | B16: 45984 | D16: ='112225'!D16 -> PTL 1-15H
A17: 16 | B17: 45984 | D17: ='112225'!D17 -> GABRIEL 2-12H
A18: 17 | B18: 45984 | D18: ='112225'!D18 -> GABRIEL 1-12H
A19: 18 | B19: 45984 | D19: ='112225'!D19 -> SEAN 1-18H
A20: 19 | B20: 45984 | D20: ='112225'!D20 -> SEAN 3119 3-18H
A21: 20 | B21: 45984 | D21: ='112225'!D21 -> ELLIS 2-19H
A22: 21 | B22: 45984 | D22: ='112225'!D22 -> BROTHERS 1-6H
A23: 22 | B23: 45984 | D23: ='112225'!D23 -> BROTHERS 2-6H
A24: 23 | B24: 45984 | C24: 0.36458333 | D24: ='112225'!D24 -> SARAH 1-34H | F24: 3 | G24: 10 | H24: 832 | I24: 54.7 | J24: 50 | K24: 33.87 | L24: 50.2 | M24: Pumping unit extremely misaligned, packing leaking bad, E-POT full, drained
A25: 24 | B25: 45984 | C25: 0.375 | D25: ='112225'!D25 -> SARAH 2-34H | F25: 4 | G25: 0 | H25: 41.7 | I25: 71 | L25: 52.4
A26: 25 | B26: 45984 | C26: 0.40833333 | D26: ='112225'!D26 -> WANDA 1-2H 1L | F26: 4 | H26: 234 | I26: 220 | L26: 50.32
A27: 26 | B27: 45984 | D27: ='112225'!D27 -> Yankee 3317 1-27 SWD
A28: 27
A29: 28
A30: 29
A31: 30
A32: 31
A33: 32
A34: 33
A35: 34
A36: 35
A37: 36
H38: =SUM(H1:H37) -> 2196.7

Sheet 112425
B1: Date | C1: Time | D1: Well Name | E1: Tank | F1: Oil (ft) | G1: Oil (in) | H1: Gas Rate | I1: Instant Gas Rate | J1: Tubing Pressure (psi) | K1: Casing Pressure (psi) | L1: Line Pressure (psi) | M1: Comments/Issues | P1: Oil Feet | Q1: Oil Inches | R1: Total Inches
A2: 1 | B2: 45985 | C2: 0.43402778 | D2: ='112225'!D2 -> RALPH BAKER 1 | F2: 3 | G2: 10 | H2: 24 | I2: 32 | J2: 120 | L2: 32 | M2: Running | P2: 3 | Q2: 10 | R2: =P2*12+Q2 -> 46
A3: 2 | B3: 45985 | C3: 0.44097222 | D3: ='112225'!D3 -> SALLY 1-12H | F3: 2 | G3: 6 | H3: 164 | I3: 149 | J3: 150 | K3: 30 | L3: 35 | M3: Running | P3: 2 | Q3: 6 | R3: =P3*12+Q3 -> 30
A4: 3 | B4: 45985 | C4: 0.45138889 | D4: ='112225'!D4 -> ANITA 1-13H | F4: 1 | G4: 0 | H4: 80 | I4: 102 | J4: 175 | K4: 5 | L4: 44 | M4: Running | P4: 1 | Q4: 0 | R4: =P4*12+Q4 -> 12
A5: 4 | B5: 45985 | C5: 0.46875 | D5: ='112225'!D5 -> ARIANA 1-18H | F5: 2 | G5: 2 | H5: 123 | I5: 144 | J5: 150 | K5: 30 | L5: 43 | M5: Running | P5: 2 | Q5: 2 | R5: =P5*12+Q5 -> 26
A6: 5 | B6: 45985 | C6: 0.41666667 | D6: ='112225'!D6 -> CLAY 1-6H | F6: 2 | G6: 9 | H6: 229 | I6: 209 | J6: 150 | K6: 30 | L6: 38 | M6: Running | P6: 2 | Q6: 9 | R6: =P6*12+Q6 -> 33
A7: 6 | B7: 45985 | C7: 0.42361111 | D7: ='112225'!D7 -> ARIANA 1-7H | F7: 1 | G7: 10 | H7: 184 | I7: 179 | J7: 80 | K7: 50 | L7: 36 | M7: Running | P7: 1 | Q7: 10 | R7: =P7*12+Q7 -> 22
A8: 7 | B8: 45985 | C8: 0.38888889 | D8: ='112225'!D8 -> PEPPER 3-4H | F8: 1 | G8: 11 | H8: 114 | I8: 64 | J8: 50 | K8: 50 | L8: 22 | M8: Running, belt blew off, down | P8: 1 | Q8: 11 | R8: =P8*12+Q8 -> 23
A9: 8 | B9: 45985 | D9: ='112225'!D9 -> PEPPER 4-4H | H9: 82 | I9: 92 | J9: 175 | K9: 30 | L9: 32 | M9: Running | R9: =P9*12+Q9 -> 0
A10: 9 | B10: 45985 | C10: 0.51041667 | D10: ='112225'!D10 -> BIRD 3319 1-6 | F10: 1 | G10: 7 | H10: 0 | I10: 0 | J10: 150 | K10: 50 | L10: 34 | M10: Running | P10: 1 | Q10: 7 | R10: =P10*12+Q10 -> 19
A11: 10 | B11: 45985 | C11: 0.51041667 | D11: ='112225'!D11 -> BIRD 3319 3-6 | H11: 41 | I11: 52 | L11: 34 | M11: Running | R11: =P11*12+Q11 -> 0
A12: 11 | B12: 45985 | C12: 0.52083333 | D12: ='112225'!D12 -> JELLISON A 11-5 | F12: 1 | G12: 8 | H12: 6 | J12: 100 | K12: 50 | M12: Running CDP 47 | P12: 1 | Q12: 8 | R12: =P12*12+Q12 -> 20
A13: 12 | B13: 45985 | C13: 0.52777778 | D13: ='112225'!D13 -> ROCK 3319 1-16H | F13: 2 | G13: 2 | H13: 144 | I13: 121 | J13: 120 | K13: 20 | L13: 31 | M13: Running | P13: 2 | Q13: 2 | R13: =P13*12+Q13 -> 26
A14: 13 | B14: 45985 | C14: 0.61111111 | D14: ='112225'!D14 -> Dixie 3120 1‐25 SWD | M14: 5614620 | R14: =P14*12+Q14 -> 0
A15: 14 | B15: 45985 | C15: 0.62152778 | D15: ='112225'!D15 -> GARLAND 1-26H | F15: 2 | G15: 8 | H15: 34 | I15: 9 | J15: 150 | K15: 50 | L15: 75 | M15: Running | P15: 2 | Q15: 8 | R15: =P15*12+Q15 -> 32
A16: 15 | B16: 45985 | C16: 0.64236111 | D16: ='112225'!D16 -> PTL 1-15H | F16: 6 | G16: 1 | H16: 56 | I16: 55 | J16: 12 | L16: 50 | M16: Running | P16: 6 | Q16: 1 | R16: =P16*12+Q16 -> 73
A17: 16 | B17: 45985 | C17: 0.66666667 | D17: ='112225'!D17 -> GABRIEL 2-12H | F17: 7 | G17: 2 | H17: 49 | I17: 116 | J17: 200 | K17: 50 | L17: 57 | M17: Running | P17: 7 | Q17: 2 | R17: =P17*12+Q17 -> 86
A18: 17 | B18: 45985 | C18: 0.6875 | D18: ='112225'!D18 -> GABRIEL 1-12H | F18: 3 | G18: 5 | H18: 42 | I18: 21 | J18: 120 | K18: 50 | L18: 56 | M18: Running | P18: 3 | Q18: 5 | R18: =P18*12+Q18 -> 41
A19: 18 | B19: 45985 | C19: 0.69791667 | D19: ='112225'!D19 -> SEAN 1-18H | F19: 7 | G19: 6 | H19: 58 | I19: 44 | J19: 150 | K19: 50 | L19: 57 | M19: Running | P19: 7 | Q19: 6 | R19: =P19*12+Q19 -> 90
A20: 19 | B20: 45985 | C20: 0.70277778 | D20: ='112225'!D20 -> SEAN 3119 3-18H | F20: 1 | G20: 11 | H20: 43 | I20: 0 | J20: 100 | K20: 50 | L20: 56 | M20: Running | P20: 1 | Q20: 11 | R20: =P20*12+Q20 -> 23
A21: 20 | B21: 45985 | C21: 0.70833333 | D21: ='112225'!D21 -> ELLIS 2-19H | F21: 5 | G21: 2 | H21: 95 | I21: 101 | J21: 150 | K21: 50 | L21: 56 | M21: Running | P21: 5 | Q21: 2 | R21: =P21*12+Q21 -> 62
A22: 21 | B22: 45985 | C22: 0.71875 | D22: ='112225'!D22 -> BROTHERS 1-6H | F22: 4 | G22: 4 | H22: 74 | I22: 0 | J22: 100 | K22: 50 | L22: 65 | M22: Down, E-POT, running | P22: 4 | Q22: 4 | R22: =P22*12+Q22 -> 52
A23: 22 | B23: 45985 | D23: ='112225'!D23 -> BROTHERS 2-6H | F23: 3 | G23: 0 | H23: 45 | I23: 135 | L23: 79 | M23: Running | P23: 3 | Q23: 0 | R23: =P23*12+Q23 -> 36
A24: 23 | B24: 45985 | C24: 0.63194444 | D24: ='112225'!D24 -> SARAH 1-34H | F24: 4 | G24: 1 | H24: 77.6 | I24: 0 | J24: 90 | K24: 30.2 | L24: 50.9 | M24: Pumping unit down, E-POT full of water and oil, started pumping unit | N24: OnPing shows Sarah 1 at 3' 11". Ron gauged at 4' 1" | P24: 4 | Q24: 1 | R24: =P24*12+Q24 -> 49
A25: 24 | B25: 45985 | C25: 0.63958333 | D25: ='112225'!D25 -> SARAH 2-34H | F25: 4 | G25: 0 | H25: 41.3 | I25: 0 | L25: 51.2 | M25: Running | N25: OnPing shows Sarah 2 at 4' 1". Ron gauged at 4' 11.5" | P25: 4 | Q25: 0 | R25: =P25*12+Q25 -> 48
A26: 25 | B26: 45985 | C26: 0.67361111 | D26: ='112225'!D26 -> WANDA 1-2H 1L | F26: 4 | G26: 1.5 | H26: 227 | I26: 227 | L26: 49.8 | M26: 157 intake psi, 170.6 temp, 682 hz | P26: 4 | Q26: 1.5 | R26: =P26*12+Q26 -> 49.5
A27: 26 | B27: 45985 | C27: 0.14722222 | D27: ='112225'!D27 -> Yankee 3317 1-27 SWD | M27: 7760249.6
A28: 27
A29: 28
A30: 29
A31: 30
A32: 31
A33: 32
A34: 33
A35: 34
A36: 35
A37: 36
H38: =SUM(H1:H37) -> 2032.9

Sheet 112525
B1: Date | C1: Time | D1: Well Name | E1: Tank | F1: Oil (ft) | G1: Oil (in) | H1: Gas Rate | I1: Instant Gas Rate | J1: Tubing Pressure (psi) | K1: Casing Pressure (psi) | L1: Line Pressure (psi) | M1: Comments/Issues | O1: Tank Factor | P1: Oil Feet | Q1: Oil Inches | R1: Total Inches | S1: New Inches of Oil | T1: New BO | V1: Gas Difference
A2: 1 | B2: 45986 | C2: 0.47569444 | D2: ='112225'!D2 -> RALPH BAKER 1 | E2: 1 | F2: 3 | G2: 11 | H2: 24 | I2: 27 | J2: 120 | K2: 0 | L2: 32 | M2: Running. No chemical | O2: 1.67 | P2: 3 | Q2: 11 | R2: =P2*12+Q2 -> 47 | S2: =R2-'112425'!R2 -> 1 | T2: =S2*O2 -> 1.67 | V2: =H2-'112425'!H2 -> 0
A3: 2 | B3: 45986 | C3: 0.44097222 | D3: ='112225'!D3 -> SALLY 1-12H | E3: 1 | F3: 2 | G3: 6 | H3: 156 | I3: 185 | J3: 100 | K3: 30 | L3: 36 | M3: Running. No chemical | O3: 1.67 | P3: 2 | Q3: 6 | R3: =P3*12+Q3 -> 30 | S3: =R3-'112425'!R3 -> 0 | T3: =S3*O3 -> 0 | V3: =H3-'112425'!H3 -> -8
A4: 3 | B4: 45986 | C4: 0.44791667 | D4: ='112225'!D4 -> ANITA 1-13H | E4: 2 | F4: 1 | G4: 0 | H4: 85 | I4: 81 | J4: 200 | K4: 50 | L4: 44 | M4: Running. No chemical | O4: 2.78 | P4: 1 | Q4: 0 | R4: =P4*12+Q4 -> 12 | S4: =R4-'112425'!R4 -> 0 | T4: =S4*O4 -> 0 | V4: =H4-'112425'!H4 -> 5
A5: 4 | B5: 45986 | C5: 0.46527778 | D5: ='112225'!D5 -> ARIANA 1-18H | E5: 1 | F5: 2 | G5: 2 | H5: 123 | I5: 145 | J5: 150 | K5: 30 | L5: 45 | M5: Running. No chemical | O5: 1.67 | P5: 2 | Q5: 2 | R5: =P5*12+Q5 -> 26 | S5: =R5-'112425'!R5 -> 0 | T5: =S5*O5 -> 0 | V5: =H5-'112425'!H5 -> 0
A6: 5 | B6: 45986 | C6: 0.40625 | D6: ='112225'!D6 -> CLAY 1-6H | E6: 1 | F6: 2 | G6: 10 | H6: 230 | I6: 268 | J6: 150 | K6: 30 | L6: 37 | M6: Running. 1/4 yellow, 0 white | O6: 1.67 | P6: 2 | Q6: 10 | R6: =P6*12+Q6 -> 34 | S6: =R6-'112425'!R6 -> 1 | T6: =S6*O6 -> 1.67 | V6: =H6-'112425'!H6 -> 1
A7: 6 | B7: 45986 | C7: 0.41666667 | D7: ='112225'!D7 -> ARIANA 1-7H | E7: 1 | F7: 1 | G7: 11 | H7: 180 | I7: 206 | J7: 80 | K7: 50 | L7: 36 | M7: Running. Full white, 0 yellow | O7: 1.67 | P7: 1 | Q7: 11 | R7: =P7*12+Q7 -> 23 | S7: =R7-'112425'!R7 -> 1 | T7: =S7*O7 -> 1.67 | V7: =H7-'112425'!H7 -> -4
A8: 7 | B8: 45986 | C8: 0.375 | D8: ='112225'!D8 -> PEPPER 3-4H | E8: 1 | F8: 1 | G8: 11 | H8: 35 | I8: 33 | L8: 32 | M8: Belts off, no chemical | O8: 1.67 | P8: 1 | Q8: 11 | R8: =P8*12+Q8 -> 23 | S8: =R8-'112425'!R8 -> 0 | T8: =S8*O8 -> 0 | V8: =H8-'112425'!H8 -> -79
A9: 8 | B9: 45986 | C9: 0.37847222 | D9: ='112225'!D9 -> PEPPER 4-4H | H9: 76 | I9: 98 | J9: 200 | K9: 50 | L9: 32 | M9: Running. No chemical | O9: 1.67 | R9: =P9*12+Q9 -> 0 | S9: =R9-'112425'!R9 -> 0 | T9: =S9*O9 -> 0 | V9: =H9-'112425'!H9 -> -6
A10: 9 | B10: 45986 | C10: 0.48611111 | D10: ='112225'!D10 -> BIRD 3319 1-6 | E10: 1 | F10: 1 | G10: 7 | H10: 0 | I10: 0 | L10: 33 | M10: Running. 0 yellow, 3/4 white | O10: 1.67 | P10: 1 | Q10: 7 | R10: =P10*12+Q10 -> 19 | S10: =R10-'112425'!R10 -> 0 | T10: =S10*O10 -> 0 | V10: =H10-'112425'!H10 -> 0
A11: 10 | B11: 45986 | D11: ='112225'!D11 -> BIRD 3319 3-6 | E11: 1 | H11: 39 | I11: 46 | L11: 33 | M11: Running. CDP 46 | O11: 1.67 | R11: =P11*12+Q11 -> 0 | S11: =R11-'112425'!R11 -> 0 | T11: =S11*O11 -> 0 | V11: =H11-'112425'!H11 -> -2
A12: 11 | B12: 45986 | D12: ='112225'!D12 -> JELLISON A 11-5 | E12: 1 | F12: 1 | G12: 8 | H12: 7 | J12: 100 | K12: 50 | M12: Running. 1/2 chemical | O12: 1.67 | P12: 1 | Q12: 8 | R12: =P12*12+Q12 -> 20 | S12: =R12-'112425'!R12 -> 0 | T12: =S12*O12 -> 0 | V12: =H12-'112425'!H12 -> 1
A13: 12 | B13: 45986 | C13: 0.50347222 | D13: ='112225'!D13 -> ROCK 3319 1-16H | E13: 1 | F13: 2 | G13: 2 | H13: 120 | I13: 128 | J13: 120 | K13: 20 | L13: 31 | M13: Running, 1/4 chemical | O13: 1.67 | P13: 2 | Q13: 2 | R13: =P13*12+Q13 -> 26 | S13: =R13-'112425'!R13 -> 0 | T13: =S13*O13 -> 0 | V13: =H13-'112425'!H13 -> -24
A14: 13 | B14: 45986 | D14: ='112225'!D14 -> Dixie 3120 1‐25 SWD | R14: =P14*12+Q14 -> 0 | S14: =R14-'112425'!R14 -> 0 | T14: =S14*O14 -> 0
A15: 14 | B15: 45986 | C15: 0.72708333 | D15: ='112225'!D15 -> GARLAND 1-26H | E15: 1 | F15: 3 | G15: 1.5 | H15: 1.6 | I15: 255 | J15: 195 | K15: 39.5 | L15: 100 | M15: Installed gas jack compressor to perform well test. Got running at noon. | O15: 1.67 | P15: 3 | Q15: 1.5 | R15: =P15*12+Q15 -> 37.5 | S15: =R15-'112425'!R15 -> 5.5 | T15: =S15*O15 -> 9.185 | V15: =H15-'112425'!H15 -> -32.4
A16: 15 | B16: 45986 | D16: ='112225'!D16 -> PTL 1-15H | E16: 1 | F16: 6 | G16: 3 | H16: 56 | I16: 55 | J16: 120 | L16: 56 | M16: Running. No chemical | O16: 1.67 | P16: 6 | Q16: 3 | R16: =P16*12+Q16 -> 75 | S16: =R16-'112425'!R16 -> 2 | T16: =S16*O16 -> 3.34 | V16: =H16-'112425'!H16 -> 0
A17: 16 | B17: 45986 | D17: ='112225'!D17 -> GABRIEL 2-12H | E17: 2 | F17: 7 | G17: 11 | H17: 54 | I17: 120 | J17: 200 | K17: 50 | M17: Running | O17: 1.67 | P17: 7 | Q17: 11 | R17: =P17*12+Q17 -> 95 | S17: =R17-'112425'!R17 -> 9 | T17: =S17*O17 -> 15.03 | V17: =H17-'112425'!H17 -> 5
A18: 17 | B18: 45986 | D18: ='112225'!D18 -> GABRIEL 1-12H | E18: 2 | F18: 3 | G18: 5 | H18: 42 | I18: 0 | J18: 100 | K18: 50 | L18: 66 | M18: Running | O18: 1.67 | P18: 3 | Q18: 5 | R18: =P18*12+Q18 -> 41 | S18: =R18-'112425'!R18 -> 0 | T18: =S18*O18 -> 0 | V18: =H18-'112425'!H18 -> 0
A19: 18 | B19: 45986 | D19: ='112225'!D19 -> SEAN 1-18H | E19: 1 | F19: 7 | G19: 8 | H19: 56 | I19: 75 | J19: 150 | K19: 50 | L19: 60 | M19: Running | O19: 1.67 | P19: 7 | Q19: 8 | R19: =P19*12+Q19 -> 92 | S19: =R19-'112425'!R19 -> 2 | T19: =S19*O19 -> 3.34 | V19: =H19-'112425'!H19 -> -2
A20: 19 | B20: 45986 | D20: ='112225'!D20 -> SEAN 3119 3-18H | E20: 1 | F20: 1 | G20: 11 | H20: 45 | I20: 0 | J20: 100 | K20: 50 | L20: 58 | M20: Running | O20: 1.67 | P20: 1 | Q20: 11 | R20: =P20*12+Q20 -> 23 | S20: =R20-'112425'!R20 -> 0 | T20: =S20*O20 -> 0 | V20: =H20-'112425'!H20 -> 2
A21: 20 | B21: 45986 | D21: ='112225'!D21 -> ELLIS 2-19H | E21: 1 | F21: 5 | G21: 4 | H21: 87 | I21: 97 | J21: 150 | K21: 50 | L21: 57 | M21: Running | O21: 1.67 | P21: 5 | Q21: 4 | R21: =P21*12+Q21 -> 64 | S21: =R21-'112425'!R21 -> 2 | T21: =S21*O21 -> 3.34 | V21: =H21-'112425'!H21 -> -8
A22: 21 | B22: 45986 | D22: ='112225'!D22 -> BROTHERS 1-6H | E22: 1 | F22: 4 | G22: 5 | H22: 11 | I22: 0 | J22: 100 | K22: 50 | L22: 60 | M22: Running | O22: 2.78 | P22: 4 | Q22: 5 | R22: =P22*12+Q22 -> 53 | S22: =R22-'112425'!R22 -> 1 | T22: =S22*O22 -> 2.78 | V22: =H22-'112425'!H22 -> -63
A23: 22 | B23: 45986 | D23: ='112225'!D23 -> BROTHERS 2-6H | E23: 1 | F23: 3 | G23: 1 | H23: 97 | I23: 127 | L23: 80 | M23: Running | O23: 2.78 | P23: 3 | Q23: 1 | R23: =P23*12+Q23 -> 37 | S23: =R23-'112425'!R23 -> 1 | T23: =S23*O23 -> 2.78 | V23: =H23-'112425'!H23 -> 52
A24: 23 | B24: 45986 | D24: ='112225'!D24 -> SARAH 1-34H | E24: 1 | F24: 4 | G24: 10 | H24: 51.74 | I24: 35.75 | L24: 45.91 | M24: Running, drained E-POT | O24: 1.67 | P24: 4 | Q24: 10 | R24: =P24*12+Q24 -> 58 | S24: =R24-'112425'!R24 -> 9 | T24: =S24*O24 -> 15.03 | V24: =H24-'112425'!H24 -> -25.86
A25: 24 | B25: 45986 | D25: ='112225'!D25 -> SARAH 2-34H | E25: 1 | F25: 4 | G25: 0 | H25: 34.25 | I25: 59.18 | L25: 53.04 | O25: 1.67 | P25: 4 | Q25: 0 | R25: =P25*12+Q25 -> 48 | S25: 0 | T25: =S25*O25 -> 0 | V25: =H25-'112425'!H25 -> -7.05
A26: 25 | B26: 45986 | D26: ='112225'!D26 -> WANDA 1-2H 1L | E26: 1 | F26: 4 | G26: 2 | H26: 227 | I26: 197 | L26: 50.47 | M26: Running. Intake psi 156.1, temp 168.2, 67 hz | O26: 2.78 | P26: 4 | Q26: 2 | R26: =P26*12+Q26 -> 50 | S26: =R26-'112425'!R26 -> 0.5 | T26: =S26*O26 -> 1.39 | V26: =H26-'112425'!H26 -> 0
A27: 26 | B27: 45986 | D27: ='112225'!D27 -> Yankee 3317 1-27 SWD
A28: 27
A29: 28
A30: 29
A31: 30
A32: 31
A33: 32
A34: 33
A35: 34
A36: 35
A37: 36
H38: =SUM(H1:H37) -> 1837.59 | S38: =SUM(S1:S37) -> 35 | T38: =SUM(T1:T37) -> 61.225

Sheet 112625
B1: Date | C1: Time | D1: Well Name | E1: Tank | F1: Oil (ft) | G1: Oil (in) | H1: Gas Rate | I1: Instant Gas Rate | J1: Tubing Pressure (psi) | K1: Casing Pressure (psi) | L1: Line Pressure (psi) | M1: Comments/Issues
A2: 1 | B2: 45987 | D2: ='112225'!D2 -> RALPH BAKER 1 | E2: 1 | F2: 4 | G2: 0 | H2: 24 | I2: 30 | J2: 120 | L2: 32 | M2: Running
A3: 2 | B3: 45987 | D3: ='112225'!D3 -> SALLY 1-12H | E3: 1 | F3: 2 | G3: 6 | H3: 157 | I3: 159 | J3: 100 | K3: 30 | L3: 36 | M3: Running
A4: 3 | B4: 45987 | D4: ='112225'!D4 -> ANITA 1-13H | E4: 2 | F4: 1 | G4: 0 | H4: 85 | I4: 88 | J4: 200 | K4: 50 | L4: 43 | M4: Running
A5: 4 | B5: 45987 | D5: ='112225'!D5 -> ARIANA 1-18H | E5: 1 | F5: 2 | G5: 3 | H5: 121 | I5: 130 | J5: 150 | K5: 30 | L5: 42 | M5: Running
A6: 5 | B6: 45987 | D6: ='112225'!D6 -> CLAY 1-6H | E6: 1 | F6: 2 | G6: 11 | H6: 230 | I6: 225 | J6: 150 | K6: 30 | L6: 37 | M6: Running
A7: 6 | B7: 45987 | D7: ='112225'!D7 -> ARIANA 1-7H | E7: 1 | F7: 2 | G7: 0 | H7: 181 | I7: 199 | J7: 80 | K7: 50 | L7: 37 | M7: Running
A8: 7 | B8: 45987 | D8: ='112225'!D8 -> PEPPER 3-4H | E8: 1 | F8: 1 | G8: 11 | H8: 36 | I8: 42 | J8: 0 | K8: 20 | L8: 31 | M8: Down, reset, running
A9: 8 | B9: 45987 | D9: ='112225'!D9 -> PEPPER 4-4H | H9: 50 | I9: 0 | J9: 50 | K9: 20 | L9: 31 | M9: Running
A10: 9 | B10: 45987 | D10: ='112225'!D10 -> BIRD 3319 1-6 | E10: 1 | F10: 1 | G10: 7 | H10: 0 | I10: 0 | J10: 150 | K10: 30 | L10: 34 | M10: Running
A11: 10 | B11: 45987 | D11: ='112225'!D11 -> BIRD 3319 3-6 | H11: 36 | I11: 120 | L11: 35 | M11: CDP 44
A12: 11 | B12: 45987 | D12: ='112225'!D12 -> JELLISON A 11-5 | E12: 1 | F12: 1 | G12: 8 | H12: 8 | J12: 100 | K12: 50 | M12: Running
A13: 12 | B13: 45987 | D13: ='112225'!D13 -> ROCK 3319 1-16H | E13: 1 | F13: 2 | G13: 2 | H13: 115 | I13: 121 | J13: 120 | K13: 2 | L13: 31 | M13: Running
A14: 13 | B14: 45987 | D14: ='112225'!D14 -> Dixie 3120 1‐25 SWD | M14: 5619142
A15: 14 | B15: 45987 | D15: ='112225'!D15 -> GARLAND 1-26H | E15: 1 | F15: 3 | G15: 1.5 | H15: 71 | I15: 0 | J15: 1.9 | K15: 1.2 | L15: 68 | M15: Unit down since 1 am, stuffing box corroded and leaked into EPOT which shut pumping unit down, well loaded up and compressor went down shortly after due to no casing gas, cleaned up mess, had a crew meet on location to lay down polish rod liner and remove stuffing box, replaced stuffing box and EPOT, started pumping unit, producing good fluid but still no casing gas, may take a day or two to unload well and return compressor to production.
A16: 15 | B16: 45987 | D16: ='112225'!D16 -> PTL 1-15H | E16: 1 | F16: 6 | G16: 10 | H16: 55 | I16: 50 | L16: 51 | M16: Running
A17: 16 | B17: 45987 | D17: ='112225'!D17 -> GABRIEL 2-12H | E17: 2 | F17: 8 | G17: 6 | H17: 47 | I17: 0 | J17: 200 | K17: 50 | L17: 57 | M17: Running
A18: 17 | B18: 45987 | D18: ='112225'!D18 -> GABRIEL 1-12H | E18: 2 | F18: 3 | G18: 8 | H18: 42 | I18: 34 | J18: 100 | K18: 50 | L18: 54 | M18: Running
A19: 18 | B19: 45987 | D19: ='112225'!D19 -> SEAN 1-18H | E19: 1 | F19: 7 | G19: 10 | H19: 55 | I19: 72 | J19: 150 | K19: 50 | L19: 54 | M19: Running
A20: 19 | B20: 45987 | D20: ='112225'!D20 -> SEAN 3119 3-18H | E20: 1 | F20: 2 | G20: 0 | H20: 28 | I20: 51 | J20: 100 | K20: 50 | L20: 51 | M20: Running
A21: 20 | B21: 45987 | D21: ='112225'!D21 -> ELLIS 2-19H | E21: 1 | F21: 5 | G21: 6 | H21: 87 | I21: 107 | J21: 150 | K21: 50 | L21: 57 | M21: Running
A22: 21 | B22: 45987 | D22: ='112225'!D22 -> BROTHERS 1-6H | E22: 1 | F22: 4 | G22: 6 | H22: 0 | I22: 0 | J22: 100 | K22: 50 | L22: 64 | M22: Down, EPOT, started
A23: 22 | B23: 45987 | D23: ='112225'!D23 -> BROTHERS 2-6H | E23: 1 | F23: 3 | G23: 2 | H23: 103 | I23: 116 | L23: 35
A24: 23 | B24: 45987 | D24: ='112225'!D24 -> SARAH 1-34H | E24: 1 | F24: 5 | G24: 0 | H24: 76 | I24: 26 | L24: 50
A25: 24 | B25: 45987 | D25: ='112225'!D25 -> SARAH 2-34H | E25: 1 | F25: 4 | G25: 0 | H25: 41 | I25: 20 | L25: 51 | M25: Intake 128.1, Temp 219.9, Volts out 455, 62.1 hz
A26: 25 | B26: 45987 | D26: ='112225'!D26 -> WANDA 1-2H 1L | E26: 1 | F26: 4 | G26: 3 | H26: 227 | I26: 255 | M26: Intake 158, Temp 170, 68 hz
A27: 26 | D27: ='112225'!D27 -> Yankee 3317 1-27 SWD | M27: 7760888
A28: 27 | B28: 45987 | D28: MURPHY 1-7H | H28: 11 | J28: 13 | K28: 13 | L28: 39 | M28: Open to sales. No casing gas
A29: 28 | D29: Lohrding 1 | M29: Truck broke down, unit is down and did not have start handle. Will start tomorrow
A30: 29
A31: 30
A32: 31
A33: 32
A34: 33
A35: 34
A36: 35
A37: 36
H38: =SUM(H1:H37) -> 1886

Sheet 112725
B1: Date | C1: Time | D1: Well Name | E1: Tank | F1: Oil (ft) | G1: Oil (in) | H1: Gas Rate | I1: Instant Gas Rate | J1: Tubing Pressure (psi) | K1: Casing Pressure (psi) | L1: Line Pressure (psi) | M1: Comments/Issues
A2: 1 | B2: 45988 | C2: 0.33333333 | D2: ='112225'!D2 -> RALPH BAKER 1 | E2: 1 | F2: 4 | G2: 1 | H2: 24 | I2: 50 | J2: 120 | L2: 32 | M2: Running
A3: 2 | B3: 45988 | D3: ='112225'!D3 -> SALLY 1-12H | E3: 1 | F3: 2 | G3: 7 | H3: 157 | I3: 147 | J3: 100 | K3: 80 | L3: 32 | M3: Running
A4: 3 | B4: 45988 | D4: ='112225'!D4 -> ANITA 1-13H | E4: 2 | F4: 1 | G4: 0 | H4: 87 | I4: 138 | J4: 200 | K4: 50 | L4: 35 | M4: Running
A5: 4 | B5: 45988 | D5: ='112225'!D5 -> ARIANA 1-18H | E5: 1 | F5: 2 | G5: 3 | H5: 121 | I5: 127 | J5: 150 | K5: 30 | L5: 42 | M5: Running
A6: 5 | B6: 45988 | D6: ='112225'!D6 -> CLAY 1-6H | E6: 1 | F6: 2 | G6: 11 | H6: 229 | I6: 0 | J6: 150 | K6: 30 | L6: 36 | M6: Running
A7: 6 | B7: 45988 | D7: ='112225'!D7 -> ARIANA 1-7H | E7: 1 | F7: 2 | G7: 0 | H7: 180 | I7: 206 | J7: 80 | K7: 50 | L7: 36 | M7: Running
A8: 7 | B8: 45988 | D8: ='112225'!D8 -> PEPPER 3-4H | E8: 1 | F8: 1 | G8: 11 | H8: 37 | I8: 0 | L8: 31 | M8: Down, need Ron. Ron went to well, found bad load cell cable, unit in hand, will order cable and replace. Ron left unit running.
A9: 8 | B9: 45988 | D9: ='112225'!D9 -> PEPPER 4-4H | H9: 0 | I9: 0 | J9: 50 | K9: 20 | L9: 30 | M9: Running
A10: 9 | B10: 45988 | D10: ='112225'!D10 -> BIRD 3319 1-6 | E10: 1 | F10: 1 | G10: 7 | H10: 0 | I10: 0 | J10: 150 | K10: 30 | L10: 35 | M10: Running
A11: 10 | B11: 45988 | D11: ='112225'!D11 -> BIRD 3319 3-6 | H11: 39 | I11: 80 | L11: 35 | M11: Running. CDP 45
A12: 11 | B12: 45988 | D12: ='112225'!D12 -> JELLISON A 11-5 | E12: 1 | F12: 1 | G12: 8 | H12: 6
A13: 12 | B13: 45988 | D13: ='112225'!D13 -> ROCK 3319 1-16H | E13: 1 | F13: 2 | G13: 2 | H13: 113 | I13: 30 | L13: 30 | M13: Down, water pump leak, Ron is on it. Ron found fittings from Roger, repaired pump, started pumping unit, running.
A14: 13 | B14: 45988 | D14: ='112225'!D14 -> Dixie 3120 1‐25 SWD | M14: 5621193
A15: 14 | B15: 45988 | D15: ='112225'!D15 -> GARLAND 1-26H | E15: 1 | F15: 3 | G15: 1.5 | H15: 3.7 | I15: 226 | J15: 155 | K15: 7 | L15: 73 | M15: Compressor running at 8 am, pulling casing down, producing fluid and gas, hopefully will run for 24 hours to get a good feel for what the well is going to do.
A16: 15 | B16: 45988 | D16: ='112225'!D16 -> PTL 1-15H | E16: 1 | F16: 7 | G16: 0 | H16: 56 | I16: 57 | J16: 150 | K16: 50 | L16: 54 | M16: Running
A17: 16 | B17: 45988 | D17: ='112225'!D17 -> GABRIEL 2-12H | E17: 2 | F17: 9 | G17: 2 | H17: 48 | I17: 23 | J17: 150 | K17: 50 | L17: 54 | M17: Running
A18: 17 | B18: 45988 | D18: ='112225'!D18 -> GABRIEL 1-12H | E18: 2 | F18: 4 | G18: 1 | H18: 47 | I18: 22 | J18: 100 | K18: 50 | L18: 51 | M18: Running
A19: 18 | B19: 45988 | D19: ='112225'!D19 -> SEAN 1-18H | E19: 1 | F19: 8 | G19: 0 | H19: 55 | I19: 54 | J19: 150 | K19: 50 | L19: 51 | M19: Running
A20: 19 | B20: 45988 | D20: ='112225'!D20 -> SEAN 3119 3-18H | E20: 1 | F20: 2 | G20: 0 | J20: 100 | K20: 50 | L20: 52 | M20: Running
A21: 20 | B21: 45988 | D21: ='112225'!D21 -> ELLIS 2-19H | E21: 1 | F21: 5 | G21: 7 | H21: 85 | I21: 95 | J21: 50 | K21: 50 | L21: 56 | M21: Running
A22: 21 | B22: 45988 | D22: ='112225'!D22 -> BROTHERS 1-6H | E22: 1 | F22: 4 | G22: 6 | H22: 1 | I22: 122 | J22: 100 | K22: 50 | L22: 70 | M22: Running
A23: 22 | B23: 45988 | D23: ='112225'!D23 -> BROTHERS 2-6H | E23: 1 | F23: 3 | G23: 2 | H23: 100 | I23: 104 | L23: 84 | M23: Running
A24: 23 | B24: 45988 | D24: ='112225'!D24 -> SARAH 1-34H | E24: 1 | F24: 5 | G24: 2 | H24: 40 | I24: 0 | L24: 50 | M24: Down, start, EPOT
A25: 24 | B25: 45988 | D25: ='112225'!D25 -> SARAH 2-34H | E25: 1 | F25: 4 | G25: 0 | H25: 44 | I25: 51 | L25: 52 | M25: Running
A26: 25 | B26: 45988 | D26: ='112225'!D26 -> WANDA 1-2H 1L | E26: 1 | F26: 4 | G26: 3.5 | H26: 228 | I26: 151 | L26: 50 | M26: Running
A27: 26 | B27: 45988 | D27: ='112225'!D27 -> Yankee 3317 1-27 SWD | M27: 7761219
A28: 27 | B28: 45988 | D28: MURPHY 1-7H | H28: 11 | I28: 1 | J28: 19 | K28: 21 | L28: 36 | M28: Gas lift well, flowing to show production only
A29: 28 | B29: 45988 | D29: Lohrding 1 | M29: Engine down, will start tomorrow.
A30: 29
A31: 30
A32: 31
A33: 32
A34: 33
A35: 34
A36: 35
A37: 36
H38: =SUM(H1:H37) -> 1711.7

Sheet 112825
B1: Date | C1: Time | D1: Well Name | E1: Tank | F1: Oil (ft) | G1: Oil (in) | H1: Gas Rate | I1: Instant Gas Rate | J1: Tubing Pressure (psi) | K1: Casing Pressure (psi) | L1: Line Pressure (psi) | M1: Comments/Issues
A2: 1 | B2: 45989 | C2: 0.33333333 | D2: ='112225'!D2 -> RALPH BAKER 1 | E2: 1 | F2: 4 | G2: 1.5 | H2: 23 | I2: 29 | J2: 120 | L2: 32 | M2: Running
A3: 2 | B3: 45989 | C3: 0.34375 | D3: ='112225'!D3 -> SALLY 1-12H | E3: 1 | F3: 2 | G3: 8 | H3: 155 | I3: 173 | J3: 100 | K3: 30 | L3: 35 | M3: Running
A4: 3 | B4: 45989 | C4: 0.35416667 | D4: ='112225'!D4 -> ANITA 1-13H | E4: 2 | F4: 1 | G4: 0 | H4: 89 | I4: 127 | J4: 200 | K4: 50 | L4: 37 | M4: Running
A5: 4 | B5: 45989 | C5: 0.36458333 | D5: ='112225'!D5 -> ARIANA 1-18H | E5: 1 | F5: 2 | G5: 3 | H5: 122 | I5: 129 | J5: 150 | K5: 30 | L5: 41 | M5: Running
A6: 5 | B6: 45989 | C6: 0.375 | D6: ='112225'!D6 -> CLAY 1-6H | E6: 1 | F6: 3 | G6: 0 | H6: 228 | I6: 0 | J6: 150 | K6: 30 | L6: 36 | M6: Running
A7: 6 | B7: 45989 | C7: 0.38541667 | D7: ='112225'!D7 -> ARIANA 1-7H | E7: 1 | F7: 2 | G7: 0 | H7: 179 | I7: 155 | J7: 80 | K7: 50 | L7: 36 | M7: Running
A8: 7 | B8: 45989 | C8: 0.39236111 | D8: ='112225'!D8 -> PEPPER 3-4H | E8: 1 | F8: 1 | G8: 11 | H8: 44 | I8: 71 | L8: 32 | M8: Running on hand
A9: 8 | B9: 45989 | D9: ='112225'!D9 -> PEPPER 4-4H | H9: 0 | I9: 0 | L9: 29 | M9: Down, not pumping, traveling valve stuck, no pump action, Jaime and Ron loaded tubing from Pepper 3, left unit running, building some fluid load then losing fluid load, will continue to check, put pump on tag and will let run through the night.
A10: 9 | B10: 45989 | C10: 0.41319444 | D10: ='112225'!D10 -> BIRD 3319 1-6 | E10: 1 | F10: 2 | G10: 0 | H10: 0 | I10: 0 | J10: 150 | K10: 30 | L10: 34 | M10: Running
A11: 10 | B11: 45989 | D11: ='112225'!D11 -> BIRD 3319 3-6 | H11: 39 | I11: 49 | L11: 34 | M11: CDP 47
A12: 11 | B12: 45989 | C12: 0.42708333 | D12: ='112225'!D12 -> JELLISON A 11-5 | E12: 1 | F12: 1 | G12: 10 | H12: 9
A13: 12 | B13: 45989 | C13: 0.4375 | D13: ='112225'!D13 -> ROCK 3319 1-16H | E13: 1 | F13: 2 | G13: 2 | H13: 34 | I13: 15 | L13: 31 | M13: Down, Hisep, reset, running
A14: 13 | B14: 45989 | C14: 0.58333333 | D14: ='112225'!D14 -> Dixie 3120 1‐25 SWD | M14: 5623463
A15: 14 | B15: 45989 | D15: ='112225'!D15 -> GARLAND 1-26H | E15: 1 | F15: 3 | G15: 3.5 | H15: 93 | I15: 139 | J15: 200 | K15: 7 | L15: 73 | M15: Compressor ran all night, producing a ton of water, making good oil, happy with results
A16: 15 | B16: 45989 | C16: 0.60416667 | D16: ='112225'!D16 -> PTL 1-15H | E16: 1 | F16: 7 | G16: 6 | H16: 34 | I16: 54 | J16: 150 | K16: 50 | L16: 50 | M16: Running
A17: 16 | B17: 45989 | D17: ='112225'!D17 -> GABRIEL 2-12H | E17: 2 | F17: 9 | G17: 7 | H17: 48 | I17: 24 | J17: 150 | K17: 50 | L17: 50 | M17: Running
A18: 17 | B18: 45989 | D18: ='112225'!D18 -> GABRIEL 1-12H | E18: 2 | F18: 4 | G18: 5 | H18: 44 | I18: 22 | J18: 100 | K18: 50 | L18: 56 | M18: Running
A19: 18 | B19: 45989 | D19: ='112225'!D19 -> SEAN 1-18H | E19: 1 | F19: 8 | G19: 2 | H19: 55 | I19: 51 | J19: 150 | K19: 50 | L19: 53 | M19: Running
A20: 19 | B20: 45989 | D20: ='112225'!D20 -> SEAN 3119 3-18H | E20: 1 | F20: 2 | G20: 0 | H20: 29 | I20: 31 | J20: 100 | K20: 50 | L20: 50 | M20: Running
A21: 20 | B21: 45989 | D21: ='112225'!D21 -> ELLIS 2-19H | E21: 1 | F21: 5 | G21: 9 | H21: 85 | I21: 94 | J21: 150 | K21: 50 | L21: 50 | M21: Running
A22: 21 | B22: 45989 | D22: ='112225'!D22 -> BROTHERS 1-6H | E22: 1 | F22: 4 | G22: 6 | H22: 44 | I22: 106 | J22: 100 | K22: 50 | L22: 71 | M22: Running
A23: 22 | B23: 45989 | D23: ='112225'!D23 -> BROTHERS 2-6H | E23: 1 | F23: 3 | G23: 3 | H23: 17 | I23: 104 | L23: 85 | M23: Running
A24: 23 | B24: 45989 | C24: 0.5 | D24: ='112225'!D24 -> SARAH 1-34H | E24: 1 | F24: 5 | G24: 3 | H24: 9 | I24: 0 | L24: 50 | M24: Down, EPOT, start
A25: 24 | B25: 45989 | C25: 0.51041667 | D25: ='112225'!D25 -> SARAH 2-34H | E25: 1 | F25: 4 | G25: 0 | H25: 46 | I25: 50 | L25: 50 | M25: Running
A26: 25 | B26: 45989 | C26: 0.54166667 | D26: ='112225'!D26 -> WANDA 1-2H 1L | E26: 1 | F26: 4 | G26: 4 | H26: 229 | I26: 160 | L26: 50 | M26: Running
A27: 26 | B27: 45989 | C27: 0.51805556 | D27: ='112225'!D27 -> Yankee 3317 1-27 SWD | M27: 7761384
A28: 27 | B28: 45989 | D28: MURPHY 1-7H | H28: 0 | I28: 0 | J28: 0 | K28: 39 | L28: 45 | M28: Well is shut in, will let casing pressure build and sell gas at later date.
A29: 28 | D29: Lohrding 1
A30: 29
A31: 30
A32: 31
A33: 32
A34: 33
A35: 34
A36: 35
A37: 36
F38: =SUM(F2:F37) -> 78 | G38: =SUM(G2:G37) -> 84 | H38: =SUM(H1:H37) -> 1655
F39: =F38*12+G38 -> 1020
F40: =F39*1.67 -> 1703.4

Sheet 112925
B1: Date | C1: Time | D1: Well Name | E1: Tank | F1: Oil (ft) | G1: Oil (in) | H1: Gas Rate | I1: Instant Gas Rate | J1: Tubing Pressure (psi) | K1: Casing Pressure (psi) | L1: Line Pressure (psi) | M1: Comments/Issues
A2: 1 | D2: ='112225'!D2 -> RALPH BAKER 1 | H2: 24 | M2: Running
A3: 2 | D3: ='112225'!D3 -> SALLY 1-12H | H3: 152 | M3: Running
A4: 3 | D4: ='112225'!D4 -> ANITA 1-13H | H4: 84 | M4: Unit down on arrival. Cleared alarm and returned to production.
A5: 4 | D5: ='112225'!D5 -> ARIANA 1-18H | H5: 122
A6: 5 | D6: ='112225'!D6 -> CLAY 1-6H | H6: 228 | M6: Well down when Jaime got to location, cleared alarm and started back up. Unknown reason for alarm
A7: 6 | D7: ='112225'!D7 -> ARIANA 1-7H | H7: 178 | M7: Well down when Jaime got to location. Cleared alarm, ESP started back up. Don't know reason for alarm. According to drive well shut down on 11/28/25 at 1328 hours
A8: 7 | D8: ='112225'!D8 -> PEPPER 3-4H | H8: 50 | M8: Now that Pepper 4 is down, expect to see increease in gas rate at Pepper 3
A9: 8 | D9: ='112225'!D9 -> PEPPER 4-4H | H9: 0 | M9: No pump action, SI at 7:30 am
A10: 9 | D10: ='112225'!D10 -> BIRD 3319 1-6 | H10: 37 | M10: Running
A11: 10 | D11: ='112225'!D11 -> BIRD 3319 3-6 | H11: 7 | M11: CDP 44
A12: 11 | D12: ='112225'!D12 -> JELLISON A 11-5 | H12: 0 | M12: Ron to start at lower hz tomorrow, necessary to keep Jellison 1-5, Bird 1-6 and Bird 3-6 (plunger well) running
A13: 12 | D13: ='112225'!D13 -> ROCK 3319 1-16H | H13: 60 | M13: Well down, cleared alarm, returned to production
A14: 13 | D14: ='112225'!D14 -> Dixie 3120 1‐25 SWD | M14: 5625677.2
A15: 14 | D15: ='112225'!D15 -> GARLAND 1-26H | E15: 1 | F15: 3 | G15: 4 | H15: 87 | I15: 168 | J15: 150 | L15: 85 | M15: Running
A16: 15 | D16: ='112225'!D16 -> PTL 1-15H | H16: 53 | I16: 65 | L16: 65
A17: 16 | D17: ='112225'!D17 -> GABRIEL 2-12H | H17: 68 | I17: 147 | J17: 63
A18: 17 | D18: ='112225'!D18 -> GABRIEL 1-12H | H18: 39 | I18: 0 | J18: 66 | M18: Running
A19: 18 | D19: ='112225'!D19 -> SEAN 1-18H | H19: 56 | I19: 67 | J19: 61 | M19: Running
A20: 19 | D20: ='112225'!D20 -> SEAN 3119 3-18H | H20: 21 | I20: 0 | J20: 67 | M20: Secondary pump fillage
A21: 20 | D21: ='112225'!D21 -> ELLIS 2-19H | H21: 70 | I21: 0 | J21: 67 | M21: Running
A22: 21 | D22: ='112225'!D22 -> BROTHERS 1-6H | H22: 81 | I22: 147 | J22: 91.2 | M22: Running
A23: 22 | D23: ='112225'!D23 -> BROTHERS 2-6H | H23: 98 | I23: 118 | J23: 91.2 | M23: Running
A24: 23 | D24: ='112225'!D24 -> SARAH 1-34H | H24: 11.8 | I24: 0 | L24: 49.2 | M24: Down, stuffing box packing
A25: 24 | D25: ='112225'!D25 -> SARAH 2-34H | H25: 40.4 | I25: 0 | L25: 50 | M25: Down on arrival, PLC kill
A26: 25 | D26: ='112225'!D26 -> WANDA 1-2H 1L | H26: 243 | I26: 60 | L26: 49.2 | M26: Down on arrival, power.
A27: 26 | D27: ='112225'!D27 -> Yankee 3317 1-27 SWD | M27: 7761546.4
A28: 27 | D28: MURPHY 1-7H | H28: 0 | I28: 0 | M28: Down, building casing psi to avoid having to P&A well.
A29: 28 | D29: Lohrding 1
A30: 29 | D30: ANITA 1-12H | H30: 0 | M30: Well is down. Break is on. Looks like it's been down a while. Need to figure out what is going on with this well.
A31: 30 | D31: JELLISON 3119
A32: 31
A33: 32
A34: 33
A35: 34
A36: 35
A37: 36
H38: =SUM(H1:H37) -> 1810.2

Sheet 113025
B1: Date | C1: Time | D1: Well Name | E1: Tank | F1: Oil (ft) | G1: Oil (in) | H1: Gas Rate | I1: Instant Gas Rate | J1: Tubing Pressure (psi) | K1: Casing Pressure (psi) | L1: Line Pressure (psi) | M1: Comments/Issues | O1: Total Inches
A2: 1 | B2: 45991 | D2: ='112225'!D2 -> RALPH BAKER 1 | M2: Shut off until water is hauled | O2: =F2*12+G2 -> 0
A3: 2 | B3: 45991 | D3: ='112225'!D3 -> SALLY 1-12H | E3: 1 | F3: 2 | G3: 10 | H3: 150 | I3: 0 | L3: 34 | M3: Down, start, high tank | O3: =F3*12+G3 -> 34
A4: 3 | B4: 45991 | D4: ='112225'!D4 -> ANITA 1-13H | E4: 1 | F4: 1 | G4: 0 | H4: 70 | I4: 85 | L4: 44 | M4: Running | O4: =F4*12+G4 -> 12
A5: 4 | B5: 45991 | D5: ='112225'!D5 -> ARIANA 1-18H | E5: 1 | F5: 2 | G5: 3 | H5: 18 | I5: 0 | L5: 41 | M5: Down, start, high tank | O5: =F5*12+G5 -> 27
A6: 5 | B6: 45991 | D6: ='112225'!D6 -> CLAY 1-6H | E6: 1 | F6: 3 | G6: 1 | H6: 123 | I6: 0 | L6: 45 | M6: Down, start, high tank | O6: =F6*12+G6 -> 37
A7: 6 | B7: 45991 | D7: ='112225'!D7 -> ARIANA 1-7H | E7: 1 | F7: 2 | G7: 0 | H7: 121 | I7: 0 | L7: 36 | M7: Down, start, high tank | O7: =F7*12+G7 -> 24
A8: 7 | B8: 45991 | D8: ='112225'!D8 -> PEPPER 3-4H | E8: 1 | F8: 1 | G8: 11 | H8: 58 | I8: 78 | L8: 31 | M8: Down, start, high tank | O8: =F8*12+G8 -> 23
A9: 8 | D9: ='112225'!D9 -> PEPPER 4-4H | O9: =F9*12+G9 -> 0
A10: 9 | B10: 45991 | D10: ='112225'!D10 -> BIRD 3319 1-6 | E10: 1 | F10: 2 | G10: 2 | H10: 0 | I10: 0 | L10: 33 | M10: Running | O10: =F10*12+G10 -> 26
A11: 10 | B11: 45991 | D11: ='112225'!D11 -> BIRD 3319 3-6 | H11: 33 | I11: 46 | L11: 33 | M11: CDP 33 | O11: =F11*12+G11 -> 0
A12: 11 | B12: 45991 | D12: ='112225'!D12 -> JELLISON A 11-5 | E12: 1 | F12: 2 | G12: 9 | H12: 0 | O12: =F12*12+G12 -> 33
A13: 12 | B13: 45991 | D13: ='112225'!D13 -> ROCK 3319 1-16H | E13: 1 | F13: 2 | G13: 2 | H13: 70 | I13: 35 | L13: 30 | M13: Down, start, high tank | O13: =F13*12+G13 -> 26
A14: 13 | D14: ='112225'!D14 -> Dixie 3120 1‐25 SWD | O14: =F14*12+G14 -> 0
A15: 14 | B15: 45991 | D15: ='112225'!D15 -> GARLAND 1-26H | E15: 1 | F15: 2 | G15: 6 | H15: 56 | I15: 73 | J15: 160 | K15: 6 | L15: 69 | M15: Running like a champ, made a ton of oil last night | O15: =F15*12+G15 -> 30
A16: 15 | B16: 45991 | D16: ='112225'!D16 -> PTL 1-15H | E16: 1 | F16: 8 | G16: 1.5 | H16: 53 | I16: 74 | J16: 180 | K16: 51 | L16: 54 | M16: Running good, full pump | O16: =F16*12+G16 -> 97.5
A17: 16 | B17: 45991 | D17: ='112225'!D17 -> GABRIEL 2-12H | E17: 2 | F17: 10 | G17: 7 | H17: 49 | I17: 42 | L17: 50 | M17: Running | O17: =F17*12+G17 -> 127
A18: 17 | B18: 45991 | D18: ='112225'!D18 -> GABRIEL 1-12H | E18: 2 | F18: 4 | G18: 9 | H18: 47 | I18: 21 | L18: 51 | M18: Running | O18: =F18*12+G18 -> 57
A19: 18 | B19: 45991 | D19: ='112225'!D19 -> SEAN 1-18H | E19: 1 | F19: 8 | G19: 4 | H19: 54 | I19: 51 | L19: 54 | M19: Running | O19: =F19*12+G19 -> 100
A20: 19 | B20: 45991 | D20: ='112225'!D20 -> SEAN 3119 3-18H | E20: 1 | F20: 2 | G20: 0 | H20: 27 | I20: 31 | L20: 50 | M20: Running | O20: =F20*12+G20 -> 24
A21: 20 | B21: 45991 | D21: ='112225'!D21 -> ELLIS 2-19H | E21: 16 | F21: 6 | G21: 0 | H21: 85 | I21: 97 | L21: 52 | M21: Running | O21: =F21*12+G21 -> 72
A22: 21 | B22: 45991 | D22: ='112225'!D22 -> BROTHERS 1-6H | E22: 1 | F22: 4 | G22: 6 | H22: 74.8 | I22: 0 | J22: 165 | K22: 68 | L22: 70.1 | M22: Running good | O22: =F22*12+G22 -> 54
A23: 22 | B23: 45991 | D23: ='112225'!D23 -> BROTHERS 2-6H | E23: 1 | F23: 3 | G23: 9 | H23: 103 | I23: 113 | L23: 84 | M23: Running good. | O23: =F23*12+G23 -> 45
A24: 23 | B24: 45991 | D24: ='112225'!D24 -> SARAH 1-34H | E24: 1 | F24: 5 | G24: 8 | H24: 8 | I24: 0 | L24: 36 | M24: Down, EPOT, Start | O24: =F24*12+G24 -> 68
A25: 24 | B25: 45991 | D25: ='112225'!D25 -> SARAH 2-34H | E25: 1 | F25: 4 | G25: 0 | H25: 27 | I25: 95 | L25: 56 | O25: =F25*12+G25 -> 48
A26: 25 | B26: 45991 | D26: ='112225'!D26 -> WANDA 1-2H 1L | E26: 1 | F26: 4 | G26: 9 | H26: 198 | I26: 247 | L26: 51 | O26: =F26*12+G26 -> 57
A27: 26 | B27: 45991 | D27: ='112225'!D27 -> Yankee 3317 1-27 SWD | M27: 7761683 | O27: =F27*12+G27 -> 0
A28: 27 | B28: 45991 | D28: MURPHY 1-7H | M28: Casing shut in, letting well build pressure | O28: =F28*12+G28 -> 0
A29: 28 | D29: Lohrding 1 | O29: =F29*12+G29 -> 0
A30: 29 | D30: ANITA 1-12H | O30: =F30*12+G30 -> 0
A31: 30 | D31: JELLISON 3119 | F31: 2 | G31: 9 | O31: =F31*12+G31 -> 33
A32: 31 | B32: 45991 | D32: Salt 3419 1-4 SWD | M32: Power failure due to high winds. Powerlines touch causing a short, knocking down multiple locations. This affects the Ariana 1-7, Ariana 1-18, Sally 1-12, Clay 1-6, Pepper 3 & 4, and the Rock, | O32: =F32*12+G32 -> 0
A33: 32
A34: 33
A35: 34
A36: 35
A37: 36
H38: =SUM(H1:H37) -> 1424.8

Sheet 12125
B1: Date | C1: Time | D1: Well Name | E1: Tank | F1: Oil (ft) | G1: Oil (in) | H1: Gas Rate | I1: Instant Gas Rate | J1: Tubing Pressure (psi) | K1: Casing Pressure (psi) | L1: Line Pressure (psi) | M1: Comments/Issues
A2: 1 | D2: ='112225'!D2 -> RALPH BAKER 1 | M2: Down, water tank full, waiting for water hauler
A3: 2 | B3: 45992 | D3: ='112225'!D3 -> SALLY 1-12H | H3: 22 | I3: 0 | L3: 35 | M3: Running
A4: 3 | B4: 45992 | D4: ='112225'!D4 -> ANITA 1-13H | H4: 120 | I4: 96 | L4: 42 | M4: Running
A5: 4 | B5: 45992 | D5: ='112225'!D5 -> ARIANA 1-18H | H5: 24 | I5: 120 | L5: 40 | M5: Running
A6: 5 | B6: 45992 | D6: ='112225'!D6 -> CLAY 1-6H | H6: 79 | I6: 98 | L6: 37 | M6: Running
A7: 6 | B7: 45992 | D7: ='112225'!D7 -> ARIANA 1-7H | H7: 34 | I7: 217 | L7: 36 | M7: Running
A8: 7 | B8: 45992 | D8: ='112225'!D8 -> PEPPER 3-4H | H8: 65 | I8: 80 | L8: 32 | M8: Running
A9: 8 | D9: ='112225'!D9 -> PEPPER 4-4H | M9: Running
A10: 9 | B10: 45992 | D10: ='112225'!D10 -> BIRD 3319 1-6 | H10: 0 | I10: 0 | L10: 33 | M10: Running
A11: 10 | B11: 45992 | D11: ='112225'!D11 -> BIRD 3319 3-6 | H11: 36 | I11: 0 | L11: 18 | M11: Running. CDP 40
A12: 11 | D12: ='112225'!D12 -> JELLISON A 11-5 | H12: 4 | M12: Running
A13: 12 | B13: 45992 | D13: ='112225'!D13 -> ROCK 3319 1-16H | H13: 72 | I13: 158 | L13: 32 | M13: Running
A14: 13 | B14: 45992 | D14: ='112225'!D14 -> Dixie 3120 1‐25 SWD | M14: Running. 5630394
A15: 14 | B15: 45992 | D15: ='112225'!D15 -> GARLAND 1-26H | E15: 2 | F15: 3 | G15: 4 | H15: 46 | I15: 0 | L15: 71 | M15: Running. Switched to Tank 2, lots of water in oil.
A16: 15 | B16: 45992 | D16: ='112225'!D16 -> PTL 1-15H | H16: 61 | I16: 65 | L16: 58 | M16: Running
A17: 16 | B17: 45992 | D17: ='112225'!D17 -> GABRIEL 2-12H | H17: 59 | I17: 46 | L17: 58 | M17: Running
A18: 17 | B18: 45992 | D18: ='112225'!D18 -> GABRIEL 1-12H | H18: 43 | I18: 11 | L18: 57 | M18: Running
A19: 18 | B19: 45992 | D19: ='112225'!D19 -> SEAN 1-18H | H19: 46 | I19: 23 | L19: 57 | M19: Running
A20: 19 | B20: 45992 | D20: ='112225'!D20 -> SEAN 3119 3-18H | H20: 40 | I20: 159 | L20: 59 | M20: Running
A21: 20 | B21: 45992 | D21: ='112225'!D21 -> ELLIS 2-19H | H21: 0 | I21: 107 | L21: 51 | M21: Running
A22: 21 | B22: 45992 | D22: ='112225'!D22 -> BROTHERS 1-6H | H22: 74 | I22: 21 | L22: 71 | M22: Running
A23: 22 | B23: 45992 | D23: ='112225'!D23 -> BROTHERS 2-6H | H23: 112 | I23: 98 | L23: 89 | M23: Running
A24: 23 | B24: 45992 | D24: ='112225'!D24 -> SARAH 1-34H | H24: 27 | I24: 14 | L24: 57 | M24: Down, Epot, start, hooked up hose from Epot to barrel, 30 gallons into barrel
A25: 24 | B25: 45992 | D25: ='112225'!D25 -> SARAH 2-34H | H25: 40 | I25: 51 | L25: 58 | M25: Running
A26: 25 | B26: 45992 | D26: ='112225'!D26 -> WANDA 1-2H 1L | H26: 256 | I26: 230 | L26: 51 | M26: Running
A27: 26 | B27: 45992 | D27: ='112225'!D27 -> Yankee 3317 1-27 SWD | M27: Running. 7761816
A28: 27 | D28: MURPHY 1-7H
A29: 28 | D29: Lohrding 1
A30: 29 | D30: ANITA 1-12H
A31: 30 | D31: JELLISON 3119
A32: 31 | D32: Salt 3419 1-4 SWD
A33: 32
A34: 33
A35: 34
A36: 35
A37: 36
H38: =SUM(H1:H37) -> 1260

Sheet 12225
B1: Date | C1: Time | D1: Well Name | E1: Tank | F1: Oil (ft) | G1: Oil (in) | H1: Gas Rate | I1: Instant Gas Rate | J1: Tubing Pressure (psi) | K1: Casing Pressure (psi) | L1: Line Pressure (psi) | M1: Comments/Issues
A2: 1 | B2: 45993 | C2: 0.33333333 | D2: ='112225'!D2 -> RALPH BAKER 1 | F2: 4 | G2: 1.5 | M2: Down, start
A3: 2 | B3: 45993 | C3: 0.34375 | D3: ='112225'!D3 -> SALLY 1-12H | E3: 1 | F3: 2 | G3: 11 | H3: 5 | I3: 0 | L3: 34 | M3: Down, Start, Hisep. Kenny found unit hisep, lost gas supply, causing unit to go down on high level
A4: 3 | B4: 45993 | C4: 0.36805556 | D4: ='112225'!D4 -> ANITA 1-13H | E4: 2 | F4: 1 | G4: 0 | H4: 155 | I4: 58 | L4: 41 | M4: Running
A5: 4 | B5: 45993 | C5: 0.36458333 | D5: ='112225'!D5 -> ARIANA 1-18H | E5: 1 | F5: 2 | G5: 3 | H5: 150 | I5: 140 | L5: 42 | M5: Running
A6: 5 | B6: 45993 | C6: 0.375 | D6: ='112225'!D6 -> CLAY 1-6H | E6: 1 | F6: 3 | G6: 1 | H6: 277 | I6: 230 | L6: 37 | M6: Running
A7: 6 | B7: 45993 | C7: 0.38541667 | D7: ='112225'!D7 -> ARIANA 1-7H | E7: 1 | F7: 2 | G7: 0 | H7: 194 | I7: 0 | L7: 37 | M7: Running
A8: 7 | B8: 45993 | C8: 0.40625 | D8: ='112225'!D8 -> PEPPER 3-4H | E8: 1 | F8: 2 | G8: 0 | H8: 57 | I8: 67 | L8: 31 | M8: Running
A9: 8 | B9: 45993 | D9: ='112225'!D9 -> PEPPER 4-4H | M9: Down
A10: 9 | B10: 45993 | D10: ='112225'!D10 -> BIRD 3319 1-6 | F10: 2 | G10: 2 | H10: 0 | I10: 0 | L10: 34 | M10: Down on high tank level. Cleared alarm and put back online.
A11: 10 | B11: 45993 | D11: ='112225'!D11 -> BIRD 3319 3-6 | H11: 36 | I11: 0 | L11: 18 | M11: Running. CDP 40
A12: 11 | B12: 45993 | D12: =#REF! -> #REF! | F12: 3 | G12: 5 | M12: ESP, shut in.
A13: 12 | B13: 45993 | C13: 0.42708333 | D13: ='112225'!D13 -> ROCK 3319 1-16H | E13: 1 | F13: 2 | G13: 2 | H13: 149 | I13: 100 | L13: 31 | M13: Running
A14: 13 | B14: 45993 | C14: 0.5 | D14: ='112225'!D14 -> Dixie 3120 1‐25 SWD | M14: 5633505
A15: 14 | B15: 45993 | C15: 0.4375 | D15: ='112225'!D15 -> GARLAND 1-26H | E15: 2 | F15: 4 | G15: 6 | H15: 37.3 | J15: 95 | K15: 30 | M15: Pumping ok, mechanic working on gas jack-ice plug
A16: 15 | B16: 45993 | C16: 0.52083333 | D16: ='112225'!D16 -> PTL 1-15H | E16: 1 | F16: 9 | G16: 1 | H16: 57 | I16: 66 | L16: 61 | M16: Running
A17: 16 | B17: 45993 | C17: 0.54166667 | D17: ='112225'!D17 -> GABRIEL 2-12H | E17: 2 | F17: 11 | G17: 8 | H17: 177 | I17: 157 | L17: 57 | M17: Running
A18: 17 | B18: 45993 | C18: 0.5625 | D18: ='112225'!D18 -> GABRIEL 1-12H | E18: 2 | F18: 7 | G18: 3 | H18: 39 | I18: 12 | L18: 58 | M18: Running
A19: 18 | B19: 45993 | C19: 0.63541667 | D19: ='112225'!D19 -> SEAN 1-18H | E19: 1 | F19: 10 | G19: 3 | H19: 46 | I19: 51 | L19: 56 | M19: Running
A20: 19 | B20: 45993 | C20: 0.65625 | D20: ='112225'!D20 -> SEAN 3119 3-18H | E20: 1 | F20: 2 | G20: 0 | H20: 43 | I20: 57 | L20: 60 | M20: Running
A21: 20 | B21: 45993 | C21: 0.67708333 | D21: ='112225'!D21 -> ELLIS 2-19H | E21: 1 | F21: 6 | G21: 0 | H21: 71 | I21: 115 | L21: 57 | M21: Running
A22: 21 | B22: 45993 | C22: 0.69791667 | D22: ='112225'!D22 -> BROTHERS 1-6H | E22: 1 | F22: 4 | G22: 10 | H22: 72 | I22: 0 | L22: 70 | M22: Running
A23: 22 | B23: 45993 | C23: 0.71875 | D23: ='112225'!D23 -> BROTHERS 2-6H | E23: 1 | F23: 4 | G23: 0 | H23: 100 | I23: 94 | L23: 87 | M23: Running
A24: 23 | B24: 45993 | C24: 0.35763889 | D24: ='112225'!D24 -> SARAH 1-34H | E24: 1 | F24: 5 | G24: 8 | H24: 22 | I24: 27 | J24: 56 | K24: 73 | L24: 54 | M24: Down on arrival, Epot overfilled, replaced stuffing box, replaced rod rotator, aligned pumping unit to flow tee, started unit
A25: 24 | B25: 45993 | C25: 0.36458333 | D25: ='112225'!D25 -> SARAH 2-34H | E25: 1 | F25: 4 | G25: 0 | H25: 41 | I25: 84 | L25: 57 | M25: Intake 140, motor temp 215, running at 62 hz, running on arrival
A26: 25 | B26: 45993 | C26: 0.52152778 | D26: ='112225'!D26 -> WANDA 1-2H 1L | E26: 1 | F26: 5 | G26: 0.5 | H26: 240 | I26: 67 | L26: 47 | M26: Pump intake 154, motor temp 169, frequency 68 hz, running on arrival
A27: 26 | B27: 45993 | C27: 0.48263889 | D27: ='112225'!D27 -> Yankee 3317 1-27 SWD | M27: 7762116
A28: 27 | B28: 45993 | D28: MURPHY 1-7H | M28: Casing shut in, building pressure
A29: 28 | B29: 45993 | C29: 0.58333333 | D29: Lohrding 1 | M29: Down, start
A30: 29 | B30: 45993 | D30: ANITA 1-12H | M30: Well is down. Break is on. Looks like it's been down a while. Need to figure out what is going on with this well.
A31: 30 | B31: 45996 | C31: 0.44791667 | D31: JELLISON 3119 | E31: 1 | F31: 3 | G31: 5 | H31: 4 | M31: Running
A32: 31 | B32: 45993 | D32: Salt 3419 1-4 SWD | M32: Display is bad, needs replaced. 560366.1
A33: 32
A34: 33
A35: 34
A36: 35
A37: 36
H38: =SUM(H2:H37) -> 1972.3

Sheet 12325
B1: Date | C1: Time | D1: Well Name | E1: Tank | F1: Oil (ft) | G1: Oil (in) | H1: Gas Rate | I1: Instant Gas Rate | J1: Tubing Pressure (psi) | K1: Casing Pressure (psi) | L1: Line Pressure (psi) | M1: Comments/Issues
A2: 1 | B2: 45994 | C2: 0.63541667 | D2: RALPH BAKER 1 | H2: 25 | I2: 29 | J2: 120 | L2: 30 | M2: Running
A3: 2 | B3: 45994 | C3: 0.35972222 | D3: SALLY 1-12H | H3: 5.7 | I3: 202 | J3: 180 | K3: 39 | L3: 35 | M3: Kenny said the casing psi was 100, causing well to pump off. Opened casing, bled down to 70 psi, card filled up. Lit heater treater. Thinks BPU is slapping and needs replaced. Suggests balance unit while belt is replaced. Ron arrived later and unit was down on high sep. Installed test gauge into vertical separate and heater treater, found current gauges were off. Vertical seperator and heater treater were trying ot operate at same pressure. The vertical separator is now set at 24 psi and the heater treater is set at 15 psi. Now the fluid from the vertical separator can dump into the heater treater and function correctly. Lit burner on treater and well is performing correctly.
A4: 3 | B4: 45994 | C4: 0.63888889 | D4: ANITA 1-13H | H4: 102 | I4: 100 | J4: 150 | K4: 50 | L4: 44 | M4: Running
A5: 4 | B5: 45994 | C5: 0.64236111 | D5: ARIANA 1-18H | H5: 123 | I5: 134 | J5: 150 | K5: 30 | L5: 37 | M5: Running
A6: 5 | B6: 45994 | C6: 0.64583333 | D6: CLAY 1-6H | H6: 243 | I6: 238 | J6: 100 | K6: 30 | L6: 37 | M6: Running
A7: 6 | B7: 45994 | C7: 0.64583333 | D7: ARIANA 1-7H | H7: 177 | I7: 199 | J7: 80 | K7: 60 | L7: 37 | M7: Running
A8: 7 | B8: 45994 | C8: 0.65625 | D8: PEPPER 3-4H | H8: 44 | I8: 48 | J8: 100 | K8: 50 | L8: 31 | M8: Down, Epot, start
A9: 8 | B9: 45994 | C9: 0.65625 | D9: PEPPER 4-4H | M9: Down
A10: 9 | B10: 45994 | D10: BIRD 3319 1-6 | H10: 0 | I10: 0 | J10: 100 | K10: 50 | L10: 34 | M10: Running
A11: 10 | B11: 45994 | C11: 0.60416667 | D11: BIRD 3319 3-6 | H11: 38 | I11: 56 | L11: 34 | M11: CDP 40
A12: 11 | B12: 45994 | D12: =#REF! -> #REF! | I12: 16
A13: 12 | B13: 45994 | C13: 0.67708333 | D13: ROCK 3319 1-16H | H13: 137 | I13: 115 | J13: 150 | K13: 50 | L13: 31 | M13: Running
A14: 13 | B14: 45994 | C14: 0.49791667 | D14: Dixie 3120 1‐25 SWD | M14: 5635232
A15: 14 | B15: 45994 | C15: 0.35416667 | D15: GARLAND 1-26H | H15: 31.5 | I15: 73 | J15: 202 | K15: 1.8 | L15: 69 | M15: Running good.
A16: 15 | B16: 45994 | C16: 0.48958333 | D16: PTL 1-15H | H16: 57 | I16: 43 | J16: 150 | K16: 50 | L16: 62 | M16: Running
A17: 16 | B17: 45994 | C17: 0.47916667 | D17: GABRIEL 2-12H | H17: 73 | I17: 157 | J17: 200 | K17: 70 | L17: 59 | M17: Running
A18: 17 | B18: 45994 | C18: 0.46875 | D18: GABRIEL 1-12H | H18: 40 | I18: 47 | J18: 100 | K18: 50 | L18: 57 | M18: Running
A19: 18 | B19: 45994 | C19: 0.46180556 | D19: SEAN 1-18H | H19: 53 | I19: 40 | J19: 120 | K19: 50 | L19: 56 | M19: Running
A20: 19 | B20: 45994 | C20: 0.45486111 | D20: SEAN 3119 3-18H | H20: 34 | I20: 110 | J20: 100 | K20: 50 | L20: 54 | M20: Running
A21: 20 | B21: 45994 | C21: 0.44791667 | D21: ELLIS 2-19H | H21: 100 | I21: 110 | J21: 150 | K21: 80 | L21: 52 | M21: Running
A22: 21 | B22: 45994 | C22: 0.42708333 | D22: BROTHERS 1-6H | H22: 70 | I22: 0 | J22: 100 | K22: 50 | L22: 69 | M22: Down, start, Epot, running
A23: 22 | B23: 45994 | C23: 0.4375 | D23: BROTHERS 2-6H | H23: 97 | I23: 107 | J23: 80 | K23: 50 | L23: 86 | M23: Running
A24: 23 | B24: 45994 | C24: 0.37222222 | D24: SARAH 1-34H | H24: 87 | I24: 90 | J24: 80 | K24: 50 | L24: 62 | M24: Running
A25: 24 | B25: 45994 | C25: 0.36805556 | D25: SARAH 2-34H | H25: 38 | I25: 38 | J25: 55 | K25: 80 | L25: 62 | M25: Running. Emerson showing flowrate of 0.000
A26: 25 | B26: 45994 | C26: 0.37569444 | D26: WANDA 1-2H 1L | H26: 236 | I26: 365 | J26: 122 | K26: 70 | L26: 51 | M26: Running
A27: 26 | B27: 45994 | C27: 0.37569444 | D27: Yankee 3317 1-27 SWD | M27: 7762431
A28: 27 | B28: 45994 | D28: MURPHY 1-7H | M28: Casing shut in, building pressure
A29: 28 | B29: 45994 | C29: 0.37569444 | D29: Lohrding 1 | M29: Engine is down. Seat on carburetor is wore out causing it to run rich and backfire. Ron getting new carburetor.
A30: 29 | B30: 45994 | D30: Anita 1-12H | M30: Well is down. Break is on. Looks like it's been down a while. Need to figure out what is going on with this well.
A31: 30 | B31: 45994 | D31: Salt 3419 1-4 SWD | M31: Display is bad, needs replaced. 560366.1
A32: 31 | B32: 45994 | D32: JELLISON A 11-5 | M32: ESP, down until further notice
A33: 32
A34: 33
A35: 34
A36: 35
A37: 36 | H37: =SUM(H2:H36) -> 1811.2

Sheet 12425
B1: Date | C1: Time | D1: Well Name | E1: Tank | F1: Oil (ft) | G1: Oil (in) | H1: Gas Rate | I1: Instant Gas Rate | J1: Tubing Pressure (psi) | K1: Casing Pressure (psi) | L1: Line Pressure (psi) | M1: Comments/Issues
A2: 1 | B2: 45995 | C2: 0.34375 | D2: RALPH BAKER 1 | E2: 1 | F2: 4 | G2: 3 | H2: 25 | I2: 30 | J2: 120 | L2: 32 | M2: Running
A3: 2 | B3: 45995 | C3: 0.35416667 | D3: SALLY 1-12H | E3: 1 | F3: 2 | G3: 11 | H3: 117 | I3: 221 | J3: 100 | K3: 50 | L3: 36 | M3: Running
A4: 3 | B4: 45995 | C4: 0.36458333 | D4: ANITA 1-13H | E4: 2 | F4: 1 | G4: 0 | H4: 121 | I4: 64 | J4: 150 | K4: 50 | L4: 44 | M4: Running
A5: 4 | B5: 45995 | C5: 0.37847222 | D5: ARIANA 1-18H | E5: 1 | F5: 2 | G5: 3 | H5: 124 | I5: 127 | J5: 150 | K5: 30 | L5: 37 | M5: Running
A6: 5 | B6: 45995 | C6: 0.38541667 | D6: CLAY 1-6H | E6: 1 | F6: 3 | G6: 2 | H6: 237 | I6: 235 | J6: 150 | K6: 30 | L6: 33 | M6: Running
A7: 6 | B7: 45995 | C7: 0.38888889 | D7: ARIANA 1-7H | E7: 1 | F7: 2 | G7: 1 | H7: 148 | I7: 214 | J7: 80 | K7: 60 | L7: 34 | M7: Running
A8: 7 | B8: 45995 | C8: 0.40277778 | D8: PEPPER 3-4H | E8: 1 | F8: 2 | G8: 0 | H8: 42 | I8: 92 | J8: 100 | K8: 50 | L8: 32 | M8: Running
A9: 8 | B9: 45995 | D9: PEPPER 4-4H | M9: Down per Jaime H.
A10: 9 | B10: 45995 | C10: 0.45138889 | D10: BIRD 3319 1-6 | E10: 1 | F10: 2 | G10: 5 | H10: 0 | I10: 0 | J10: 100 | K10: 50 | L10: 33 | M10: Running
A11: 10 | B11: 45995 | D11: BIRD 3319 3-6 | H11: 37 | I11: 0 | L11: 33 | M11: CDP 42. Ron working on.
A12: 11 | B12: 45995 | C12: 0.46180556 | D12: =#REF! -> #REF! | E12: 1 | F12: 4 | G12: 2 | H12: 5 | J12: 100 | K12: 50 | M12: Running
A13: 12 | B13: 45995 | C13: 0.43055556 | D13: ROCK 3319 1-16H | E13: 1 | F13: 2 | G13: 2 | H13: 70 | I13: 60 | J13: 100 | K13: 30 | L13: 70 | M13: Running
A14: 13 | B14: 45995 | C14: 0.73611111 | D14: Dixie 3120 1‐25 SWD | M14: 5638667
A15: 14 | B15: 45995 | C15: 0.72569444 | D15: GARLAND 1-26H | E15: 2 | F15: 5 | G15: 6 | H15: 36 | I15: 0 | J15: 150 | M15: Running. Approx. 4' water in tank in oil tank
A16: 15 | B16: 45995 | C16: 0.70486111 | D16: PTL 1-15H | E16: 1 | F16: 10 | G16: 3 | H16: 56 | I16: 60 | J16: 100 | K16: 50 | L16: 63 | M16: Running. Not showing water in oil tank
A17: 16 | B17: 45995 | C17: 0.69444444 | D17: GABRIEL 2-12H | E17: 1 | F17: 5 | G17: 6 | H17: 44 | I17: 0 | J17: 150 | K17: 50 | L17: 56 | M17: Running
A18: 17 | B18: 45995 | C18: 0.68402778 | D18: GABRIEL 1-12H | E18: 2 | F18: 8 | G18: 0 | H18: 41 | I18: 51 | J18: 100 | K18: 50 | L18: 57 | M18: Running
A19: 18 | B19: 45995 | C19: 0.67361111 | D19: SEAN 1-18H | E19: 1 | F19: 11 | G19: 0 | H19: 50 | I19: 60 | J19: 130 | K19: 50 | L19: 57 | M19: Running. Not showing water in oil tank
A20: 19 | B20: 45995 | C20: 0.66666667 | D20: SEAN 3119 3-18H | E20: 1 | F20: 2 | G20: 0 | H20: 36 | I20: 30 | J20: 100 | K20: 50 | L20: 54 | M20: Running
A21: 20 | B21: 45995 | C21: 0.65972222 | D21: ELLIS 2-19H | E21: 1 | F21: 6 | G21: 1 | H21: 98 | I21: 0 | J21: 100 | K21: 50 | L21: 58 | M21: Running
A22: 21 | B22: 45995 | C22: 0.64236111 | D22: BROTHERS 1-6H | E22: 1 | F22: 5 | G22: 2 | H22: 65 | I22: 140 | J22: 100 | K22: 50 | L22: 72 | M22: Running
A23: 22 | B23: 45995 | C23: 0.64652778 | D23: BROTHERS 2-6H | E23: 1 | F23: 4 | G23: 3 | H23: 97 | I23: 101 | J23: 80 | K23: 60 | L23: 88 | M23: Running
A24: 23 | B24: 45995 | C24: 0.54861111 | D24: SARAH 1-34H | E24: 1 | F24: 5 | G24: 10 | H24: 91 | I24: 59 | J24: 60 | K24: 60 | L24: 59 | M24: Running. Not showing water in oil tank
A25: 24 | B25: 45995 | C25: 0.54861111 | D25: SARAH 2-34H | E25: 1 | F25: 4 | G25: 0 | H25: 41 | I25: 40 | J25: 75 | K25: 50 | L25: 60 | M25: Running. Not showing water in oil tank. Emerson showing flowrate of 0.000
A26: 25 | B26: 45995 | C26: 0.57986111 | D26: WANDA 1-2H 1L | E26: 1 | F26: 5 | G26: 4 | H26: 244 | I26: 266 | J26: 60 | K26: 80 | L26: 58 | M26: Running
A27: 26 | B27: 45995 | C27: 0.55763889 | D27: Yankee 3317 1-27 SWD | M27: 7762584
A28: 27 | D28: MURPHY 1-7H | M28: Casing shut in, building pressure
A29: 28 | D29: Lohrding 1 | M29: Engine is down. Seat on carburetor is wore out causing it to run rich and backfire. Ron getting new carburetor.
A30: 29 | D30: Anita 1-12H | M30: Well is down. Break is on. Looks like it's been down a while. Need to figure out what is going on with this well.
A31: 30 | D31: Salt 3419 1-4 SWD | M31: Display is bad, needs replaced. 560366.1
A32: 31 | D32: JELLISON A 11-5 | M32: ESP, down until further notice
A33: 32
A34: 33
A35: 34
A36: 35
A37: 36 | H37: =SUM(H2:H36) -> 1825

Sheet 12525
B1: Date | C1: Time | D1: Well Name | E1: Tank | F1: Oil (ft) | G1: Oil (in) | H1: Gas Rate | I1: Instant Gas Rate | J1: Tubing Pressure (psi) | K1: Casing Pressure (psi) | L1: Line Pressure (psi) | M1: Comments/Issues
A2: 1 | B2: 45996 | C2: 0.40694444 | D2: RALPH BAKER 1 | H2: 24 | I2: 31 | J2: 120 | L2: 32 | M2: Running
A3: 2 | B3: 45996 | C3: 0.41180556 | D3: SALLY 1-12H | H3: 214 | I3: 176 | J3: 120 | K3: 50 | L3: 36 | M3: Running
A4: 3 | B4: 45996 | C4: 0.43819444 | D4: ANITA 1-13H | H4: 79 | I4: 80 | J4: 150 | K4: 50 | L4: 44 | M4: Running
A5: 4 | B5: 45996 | C5: 0.44583333 | D5: ARIANA 1-18H | H5: 112 | I5: 84 | J5: 150 | K5: 30 | L5: 43 | M5: Running
A6: 5 | B6: 45996 | C6: 0.45138889 | D6: CLAY 1-6H | H6: 234 | I6: 250 | J6: 150 | K6: 30 | L6: 37 | M6: Running
A7: 6 | B7: 45996 | C7: 0.45486111 | D7: ARIANA 1-7H | H7: 163 | I7: 200 | J7: 80 | K7: 60 | L7: 36 | M7: Running
A8: 7 | B8: 45996 | C8: 0.46527778 | D8: PEPPER 3-4H | H8: 56 | I8: 38 | J8: 100 | K8: 50 | L8: 56 | M8: Running
A9: 8 | B9: 45996 | D9: PEPPER 4-4H | M9: Down per Jaime H.
A10: 9 | B10: 45996 | D10: BIRD 3319 1-6 | M10: CDP 18
A11: 10 | B11: 45996 | D11: BIRD 3319 3-6 | H11: 11 | I11: 0
A12: 11 | B12: 45996 | D12: =#REF! -> #REF! | H12: 7
A13: 12 | B13: 45996 | C13: 0.47569444 | D13: ROCK 3319 1-16H | H13: 25 | I13: 31 | J13: 100 | K13: 50 | L13: 30 | M13: Running
A14: 13 | B14: 45996 | C14: 0.51041667 | D14: Dixie 3120 1‐25 SWD | M14: 5640366
A15: 14 | B15: 45996 | C15: 0.51736111 | D15: GARLAND 1-26H | H15: 34 | I15: 0 | J15: 100 | L15: 69 | M15: Running
A16: 15 | B16: 45996 | C16: 0.52430556 | D16: PTL 1-15H | H16: 54 | I16: 54 | J16: 100 | K16: 50 | L16: 62 | M16: Running
A17: 16 | B17: 45996 | C17: 0.53472222 | D17: GABRIEL 2-12H | H17: 143 | I17: 60 | J17: 150 | K17: 50 | L17: 57 | M17: Running
A18: 17 | B18: 45996 | C18: 0.54166667 | D18: GABRIEL 1-12H | H18: 80 | I18: 103 | J18: 100 | K18: 50 | L18: 56 | M18: Running
A19: 18 | B19: 45996 | C19: 0.54861111 | D19: SEAN 1-18H | H19: 49 | I19: 68 | J19: 130 | K19: 50 | L19: 58 | M19: Running
A20: 19 | B20: 45996 | C20: 0.55208333 | D20: SEAN 3119 3-18H | H20: 38 | I20: 0 | J20: 100 | K20: 50 | L20: 54 | M20: Running
A21: 20 | B21: 45996 | C21: 0.55555556 | D21: ELLIS 2-19H | H21: 43 | I21: 66 | J21: 100 | K21: 50 | L21: 55 | M21: Running
